
--- ERROR LOG ---
Timestamp: 07-082025_20-34-59
Context: Unhandled exception in main()
Exception: log_error_to_file() missing 1 required positional argument: 'error_log_path'
Traceback:
Traceback (most recent call last):
  File "c:\Users\FlowChemIR_User\Desktop\AGS Users\Meg\Automating-inline-IR-analysis-for-optimising-synthetic-reactions-MSc-project-1\metadata_utils.py", line 21, in get_probe1_data
    value_of_node = child.get_value()
  File "C:\Users\FlowChemIR_User\AppData\Local\Programs\Python\Python313\Lib\site-packages\opcua\common\node.py", line 155, in get_value
    result = self.get_data_value()
  File "C:\Users\FlowChemIR_User\AppData\Local\Programs\Python\Python313\Lib\site-packages\opcua\common\node.py", line 164, in get_data_value
    return self.get_attribute(ua.AttributeIds.Value)
           ~~~~~~~~~~~~~~~~~~^^^^^^^^^^^^^^^^^^^^^^^
  File "C:\Users\FlowChemIR_User\AppData\Local\Programs\Python\Python313\Lib\site-packages\opcua\common\node.py", line 276, in get_attribute
    result[0].StatusCode.check()
    ~~~~~~~~~~~~~~~~~~~~~~~~~~^^
  File "C:\Users\FlowChemIR_User\AppData\Local\Programs\Python\Python313\Lib\site-packages\opcua\ua\uatypes.py", line 218, in check
    raise UaStatusCodeError(self.value)
opcua.ua.uaerrors._auto.BadAttributeIdInvalid: "The attribute is not supported for the specified Node."(BadAttributeIdInvalid)

During handling of the above exception, another exception occurred:

Traceback (most recent call last):
  File "c:\Users\FlowChemIR_User\Desktop\AGS Users\Meg\Automating-inline-IR-analysis-for-optimising-synthetic-reactions-MSc-project-1\metadata_utils.py", line 30, in get_probe1_data
    if e.status == ua.StatusCodes.BadAttributeIdInvalid:
       ^^^^^^^^
AttributeError: 'BadAttributeIdInvalid' object has no attribute 'status'

During handling of the above exception, another exception occurred:

Traceback (most recent call last):
  File "c:\Users\FlowChemIR_User\Desktop\AGS Users\Meg\Automating-inline-IR-analysis-for-optimising-synthetic-reactions-MSc-project-1\main.py", line 70, in main
    probe_data = get_probe1_data(client, PROBE_1_NODE_ID)
  File "c:\Users\FlowChemIR_User\Desktop\AGS Users\Meg\Automating-inline-IR-analysis-for-optimising-synthetic-reactions-MSc-project-1\metadata_utils.py", line 45, in get_probe1_data
    log_error_to_file(
    ~~~~~~~~~~~~~~~~~^
        context_message=f"Failed to read Probe 1 node '{probe1_node_id}'",
        ^^^^^^^^^^^^^^^^^^^^^^^^^^^^^^^^^^^^^^^^^^^^^^^^^^^^^^^^^^^^^^^^^^
        exception=e
        ^^^^^^^^^^^
    )
    ^
TypeError: log_error_to_file() missing 1 required positional argument: 'error_log_path'
------------------------------------------------------------
